[2025-02-20T05:00:13.272+0000] {local_task_job_runner.py:123} INFO - ::group::Pre task execution logs
[2025-02-20T05:00:13.283+0000] {taskinstance.py:2613} INFO - Dependencies all met for dep_context=non-requeueable deps ti=<TaskInstance: postgres_fetch_dag__v2.fetch_postgres_data scheduled__2025-02-19T00:00:00+00:00 [queued]>
[2025-02-20T05:00:13.290+0000] {taskinstance.py:2613} INFO - Dependencies all met for dep_context=requeueable deps ti=<TaskInstance: postgres_fetch_dag__v2.fetch_postgres_data scheduled__2025-02-19T00:00:00+00:00 [queued]>
[2025-02-20T05:00:13.290+0000] {taskinstance.py:2866} INFO - Starting attempt 4 of 4
[2025-02-20T05:00:13.297+0000] {taskinstance.py:2889} INFO - Executing <Task(PythonOperator): fetch_postgres_data> on 2025-02-19 00:00:00+00:00
[2025-02-20T05:00:13.304+0000] {logging_mixin.py:190} WARNING - /home/***/.local/lib/python3.12/site-packages/***/task/task_runner/standard_task_runner.py:70 DeprecationWarning: This process (pid=1205) is multi-threaded, use of fork() may lead to deadlocks in the child.
[2025-02-20T05:00:13.303+0000] {standard_task_runner.py:104} INFO - Running: ['***', 'tasks', 'run', 'postgres_fetch_dag__v2', 'fetch_postgres_data', 'scheduled__2025-02-19T00:00:00+00:00', '--job-id', '619', '--raw', '--subdir', 'DAGS_FOLDER/retr.py', '--cfg-path', '/tmp/tmpz72h3vu3']
[2025-02-20T05:00:13.305+0000] {standard_task_runner.py:72} INFO - Started process 1206 to run task
[2025-02-20T05:00:13.305+0000] {standard_task_runner.py:105} INFO - Job 619: Subtask fetch_postgres_data
[2025-02-20T05:00:13.340+0000] {task_command.py:467} INFO - Running <TaskInstance: postgres_fetch_dag__v2.fetch_postgres_data scheduled__2025-02-19T00:00:00+00:00 [running]> on host 063e621c401a
[2025-02-20T05:00:13.405+0000] {taskinstance.py:3132} INFO - Exporting env vars: AIRFLOW_CTX_DAG_OWNER='***' AIRFLOW_CTX_DAG_ID='postgres_fetch_dag__v2' AIRFLOW_CTX_TASK_ID='fetch_postgres_data' AIRFLOW_CTX_EXECUTION_DATE='2025-02-19T00:00:00+00:00' AIRFLOW_CTX_TRY_NUMBER='4' AIRFLOW_CTX_DAG_RUN_ID='scheduled__2025-02-19T00:00:00+00:00'
[2025-02-20T05:00:13.406+0000] {taskinstance.py:731} INFO - ::endgroup::
[2025-02-20T05:00:13.422+0000] {base.py:84} INFO - Retrieving connection 'postgres'
[2025-02-20T05:00:13.479+0000] {taskinstance.py:3311} ERROR - Task failed with exception
Traceback (most recent call last):
  File "/home/airflow/.local/lib/python3.12/site-packages/airflow/models/taskinstance.py", line 767, in _execute_task
    result = _execute_callable(context=context, **execute_callable_kwargs)
             ^^^^^^^^^^^^^^^^^^^^^^^^^^^^^^^^^^^^^^^^^^^^^^^^^^^^^^^^^^^^^
  File "/home/airflow/.local/lib/python3.12/site-packages/airflow/models/taskinstance.py", line 733, in _execute_callable
    return ExecutionCallableRunner(
           ^^^^^^^^^^^^^^^^^^^^^^^^
  File "/home/airflow/.local/lib/python3.12/site-packages/airflow/utils/operator_helpers.py", line 252, in run
    return self.func(*args, **kwargs)
           ^^^^^^^^^^^^^^^^^^^^^^^^^^
  File "/home/airflow/.local/lib/python3.12/site-packages/airflow/models/baseoperator.py", line 422, in wrapper
    return func(self, *args, **kwargs)
           ^^^^^^^^^^^^^^^^^^^^^^^^^^^
  File "/home/airflow/.local/lib/python3.12/site-packages/airflow/operators/python.py", line 238, in execute
    return_value = self.execute_callable()
                   ^^^^^^^^^^^^^^^^^^^^^^^
  File "/home/airflow/.local/lib/python3.12/site-packages/airflow/operators/python.py", line 256, in execute_callable
    return runner.run(*self.op_args, **self.op_kwargs)
           ^^^^^^^^^^^^^^^^^^^^^^^^^^^^^^^^^^^^^^^^^^^
  File "/home/airflow/.local/lib/python3.12/site-packages/airflow/utils/operator_helpers.py", line 252, in run
    return self.func(*args, **kwargs)
           ^^^^^^^^^^^^^^^^^^^^^^^^^^
  File "/opt/airflow/dags/retr.py", line 13, in fetch_data_from_postgres
    connection = psycopg2.connect(
                 ^^^^^^^^^^^^^^^^^
  File "/home/airflow/.local/lib/python3.12/site-packages/psycopg2/__init__.py", line 122, in connect
    conn = _connect(dsn, connection_factory=connection_factory, **kwasync)
           ^^^^^^^^^^^^^^^^^^^^^^^^^^^^^^^^^^^^^^^^^^^^^^^^^^^^^^^^^^^^^^^
psycopg2.OperationalError: connection to server at "w3.training5.modak.com" (10.50.0.234), port 5432 failed: Connection refused
	Is the server running on that host and accepting TCP/IP connections?

[2025-02-20T05:00:13.496+0000] {taskinstance.py:1225} INFO - Marking task as FAILED. dag_id=postgres_fetch_dag__v2, task_id=fetch_postgres_data, run_id=scheduled__2025-02-19T00:00:00+00:00, execution_date=20250219T000000, start_date=20250220T050013, end_date=20250220T050013
[2025-02-20T05:00:13.510+0000] {taskinstance.py:340} INFO - ::group::Post task execution logs
[2025-02-20T05:00:13.511+0000] {standard_task_runner.py:124} ERROR - Failed to execute job 619 for task fetch_postgres_data (connection to server at "w3.training5.modak.com" (10.50.0.234), port 5432 failed: Connection refused
	Is the server running on that host and accepting TCP/IP connections?
; 1206)
Traceback (most recent call last):
  File "/home/airflow/.local/lib/python3.12/site-packages/airflow/task/task_runner/standard_task_runner.py", line 117, in _start_by_fork
    ret = args.func(args, dag=self.dag)
          ^^^^^^^^^^^^^^^^^^^^^^^^^^^^^
  File "/home/airflow/.local/lib/python3.12/site-packages/airflow/cli/cli_config.py", line 49, in command
    return func(*args, **kwargs)
           ^^^^^^^^^^^^^^^^^^^^^
  File "/home/airflow/.local/lib/python3.12/site-packages/airflow/utils/cli.py", line 116, in wrapper
    return f(*args, **kwargs)
           ^^^^^^^^^^^^^^^^^^
  File "/home/airflow/.local/lib/python3.12/site-packages/airflow/cli/commands/task_command.py", line 483, in task_run
    task_return_code = _run_task_by_selected_method(args, _dag, ti)
                       ^^^^^^^^^^^^^^^^^^^^^^^^^^^^^^^^^^^^^^^^^^^^
  File "/home/airflow/.local/lib/python3.12/site-packages/airflow/cli/commands/task_command.py", line 256, in _run_task_by_selected_method
    return _run_raw_task(args, ti)
           ^^^^^^^^^^^^^^^^^^^^^^^
  File "/home/airflow/.local/lib/python3.12/site-packages/airflow/cli/commands/task_command.py", line 341, in _run_raw_task
    return ti._run_raw_task(
           ^^^^^^^^^^^^^^^^^
  File "/home/airflow/.local/lib/python3.12/site-packages/airflow/utils/session.py", line 97, in wrapper
    return func(*args, session=session, **kwargs)
           ^^^^^^^^^^^^^^^^^^^^^^^^^^^^^^^^^^^^^^
  File "/home/airflow/.local/lib/python3.12/site-packages/airflow/models/taskinstance.py", line 3005, in _run_raw_task
    return _run_raw_task(
           ^^^^^^^^^^^^^^
  File "/home/airflow/.local/lib/python3.12/site-packages/airflow/models/taskinstance.py", line 273, in _run_raw_task
    TaskInstance._execute_task_with_callbacks(
  File "/home/airflow/.local/lib/python3.12/site-packages/airflow/models/taskinstance.py", line 3159, in _execute_task_with_callbacks
    result = self._execute_task(context, task_orig)
             ^^^^^^^^^^^^^^^^^^^^^^^^^^^^^^^^^^^^^^
  File "/home/airflow/.local/lib/python3.12/site-packages/airflow/models/taskinstance.py", line 3183, in _execute_task
    return _execute_task(self, context, task_orig)
           ^^^^^^^^^^^^^^^^^^^^^^^^^^^^^^^^^^^^^^^
  File "/home/airflow/.local/lib/python3.12/site-packages/airflow/models/taskinstance.py", line 767, in _execute_task
    result = _execute_callable(context=context, **execute_callable_kwargs)
             ^^^^^^^^^^^^^^^^^^^^^^^^^^^^^^^^^^^^^^^^^^^^^^^^^^^^^^^^^^^^^
  File "/home/airflow/.local/lib/python3.12/site-packages/airflow/models/taskinstance.py", line 733, in _execute_callable
    return ExecutionCallableRunner(
           ^^^^^^^^^^^^^^^^^^^^^^^^
  File "/home/airflow/.local/lib/python3.12/site-packages/airflow/utils/operator_helpers.py", line 252, in run
    return self.func(*args, **kwargs)
           ^^^^^^^^^^^^^^^^^^^^^^^^^^
  File "/home/airflow/.local/lib/python3.12/site-packages/airflow/models/baseoperator.py", line 422, in wrapper
    return func(self, *args, **kwargs)
           ^^^^^^^^^^^^^^^^^^^^^^^^^^^
  File "/home/airflow/.local/lib/python3.12/site-packages/airflow/operators/python.py", line 238, in execute
    return_value = self.execute_callable()
                   ^^^^^^^^^^^^^^^^^^^^^^^
  File "/home/airflow/.local/lib/python3.12/site-packages/airflow/operators/python.py", line 256, in execute_callable
    return runner.run(*self.op_args, **self.op_kwargs)
           ^^^^^^^^^^^^^^^^^^^^^^^^^^^^^^^^^^^^^^^^^^^
  File "/home/airflow/.local/lib/python3.12/site-packages/airflow/utils/operator_helpers.py", line 252, in run
    return self.func(*args, **kwargs)
           ^^^^^^^^^^^^^^^^^^^^^^^^^^
  File "/opt/airflow/dags/retr.py", line 13, in fetch_data_from_postgres
    connection = psycopg2.connect(
                 ^^^^^^^^^^^^^^^^^
  File "/home/airflow/.local/lib/python3.12/site-packages/psycopg2/__init__.py", line 122, in connect
    conn = _connect(dsn, connection_factory=connection_factory, **kwasync)
           ^^^^^^^^^^^^^^^^^^^^^^^^^^^^^^^^^^^^^^^^^^^^^^^^^^^^^^^^^^^^^^^
psycopg2.OperationalError: connection to server at "w3.training5.modak.com" (10.50.0.234), port 5432 failed: Connection refused
	Is the server running on that host and accepting TCP/IP connections?

[2025-02-20T05:00:13.558+0000] {local_task_job_runner.py:266} INFO - Task exited with return code 1
[2025-02-20T05:00:13.582+0000] {taskinstance.py:3895} INFO - 0 downstream tasks scheduled from follow-on schedule check
[2025-02-20T05:00:13.583+0000] {local_task_job_runner.py:245} INFO - ::endgroup::
